Workbook

Sheet orders
A1: order_id | B1: date | C1: customer_id | D1: product_id | E1: qty | F1: customer_name | G1: product_name | H1: price (in INR) | I1: total_price
A2: 1125 | B2: 44958 | C2: 11 | D2: 704 | E2: 6 | F2: =VLOOKUP(orders[[#All],[customer_id]],'customers'!A:B,2,0) -> AnthoNY | G2: =INDEX(products!A:G,MATCH(orders[[#This Row],[product_id]],products[[#All],[product_id]],0),MATCH("product_name",products[#Headers],0)) -> Eggs | H2: =VLOOKUP(orders[[#This Row],[product_id]],products!A:G,7,FALSE) -> ₹65 | I2: =SUM(orders[[#This Row],[qty]]*orders[[#This Row],[price (in INR)]]) -> 390
A3: 1127 | B3: 44958 | C3: 19 | D3: 392 | E3: 2 | F3: =VLOOKUP(orders[[#All],[customer_id]],'customers'!A:B,2,0) -> ahmeD | G3: =INDEX(products!A:G,MATCH(orders[[#This Row],[product_id]],products[[#All],[product_id]],0),MATCH("product_name",products[#Headers],0)) -> Yogurt | H3: =VLOOKUP(orders[[#This Row],[product_id]],products!A:G,7,FALSE) -> ₹30 | I3: =SUM(orders[[#This Row],[qty]]*orders[[#This Row],[price (in INR)]]) -> 60
A4: 1152 | B4: 44958 | C4: 14 | D4: 646 | E4: 7 | F4: =VLOOKUP(orders[[#All],[customer_id]],'customers'!A:B,2,0) -> RavI | G4: =INDEX(products!A:G,MATCH(orders[[#This Row],[product_id]],products[[#All],[product_id]],0),MATCH("product_name",products[#Headers],0)) -> Apple | H4: =VLOOKUP(orders[[#This Row],[product_id]],products!A:G,7,FALSE) -> ₹200 | I4: =SUM(orders[[#This Row],[qty]]*orders[[#This Row],[price (in INR)]]) -> 1400
A5: 1153 | B5: 44958 | C5: 35 | D5: 294 | E5: 9 | F5: =VLOOKUP(orders[[#All],[customer_id]],'customers'!A:B,2,0) -> MiKe | G5: =INDEX(products!A:G,MATCH(orders[[#This Row],[product_id]],products[[#All],[product_id]],0),MATCH("product_name",products[#Headers],0)) -> Rice | H5: =VLOOKUP(orders[[#This Row],[product_id]],products!A:G,7,FALSE) -> ₹80 | I5: =SUM(orders[[#This Row],[qty]]*orders[[#This Row],[price (in INR)]]) -> 720
A6: 1161 | B6: 44958 | C6: 35 | D6: 651 | E6: 6 | F6: =VLOOKUP(orders[[#All],[customer_id]],'customers'!A:B,2,0) -> MiKe | G6: =INDEX(products!A:G,MATCH(orders[[#This Row],[product_id]],products[[#All],[product_id]],0),MATCH("product_name",products[#Headers],0)) -> Banana | H6: =VLOOKUP(orders[[#This Row],[product_id]],products!A:G,7,FALSE) -> ₹80 | I6: =SUM(orders[[#This Row],[qty]]*orders[[#This Row],[price (in INR)]]) -> 480
A7: 1163 | B7: 44959 | C7: 50 | D7: 646 | E7: 4 | F7: =VLOOKUP(orders[[#All],[customer_id]],'customers'!A:B,2,0) -> BRuce | G7: =INDEX(products!A:G,MATCH(orders[[#This Row],[product_id]],products[[#All],[product_id]],0),MATCH("product_name",products[#Headers],0)) -> Apple | H7: =VLOOKUP(orders[[#This Row],[product_id]],products!A:G,7,FALSE) -> ₹200 | I7: =SUM(orders[[#This Row],[qty]]*orders[[#This Row],[price (in INR)]]) -> 800
A8: 1167 | B8: 44959 | C8: 35 | D8: 739 | E8: 9 | F8: =VLOOKUP(orders[[#All],[customer_id]],'customers'!A:B,2,0) -> MiKe | G8: =INDEX(products!A:G,MATCH(orders[[#This Row],[product_id]],products[[#All],[product_id]],0),MATCH("product_name",products[#Headers],0)) -> Donut | H8: =VLOOKUP(orders[[#This Row],[product_id]],products!A:G,7,FALSE) -> ₹40 | I8: =SUM(orders[[#This Row],[qty]]*orders[[#This Row],[price (in INR)]]) -> 360
A9: 1167 | B9: 44959 | C9: 35 | D9: 739 | E9: 8 | F9: =VLOOKUP(orders[[#All],[customer_id]],'customers'!A:B,2,0) -> MiKe | G9: =INDEX(products!A:G,MATCH(orders[[#This Row],[product_id]],products[[#All],[product_id]],0),MATCH("product_name",products[#Headers],0)) -> Donut | H9: =VLOOKUP(orders[[#This Row],[product_id]],products!A:G,7,FALSE) -> ₹40 | I9: =SUM(orders[[#This Row],[qty]]*orders[[#This Row],[price (in INR)]]) -> 320
A10: 1176 | B10: 44959 | C10: 11 | D10: 628 | E10: 5 | F10: =VLOOKUP(orders[[#All],[customer_id]],'customers'!A:B,2,0) -> AnthoNY | G10: =INDEX(products!A:G,MATCH(orders[[#This Row],[product_id]],products[[#All],[product_id]],0),MATCH("product_name",products[#Headers],0)) -> Fish | H10: =VLOOKUP(orders[[#This Row],[product_id]],products!A:G,7,FALSE) -> ₹120 | I10: =SUM(orders[[#This Row],[qty]]*orders[[#This Row],[price (in INR)]]) -> 600
A11: 1183 | B11: 44959 | C11: 21 | D11: 163 | E11: 7 | F11: =VLOOKUP(orders[[#All],[customer_id]],'customers'!A:B,2,0) -> Lisa | G11: =INDEX(products!A:G,MATCH(orders[[#This Row],[product_id]],products[[#All],[product_id]],0),MATCH("product_name",products[#Headers],0)) -> Grape Juice | H11: =VLOOKUP(orders[[#This Row],[product_id]],products!A:G,7,FALSE) -> ₹40 | I11: =SUM(orders[[#This Row],[qty]]*orders[[#This Row],[price (in INR)]]) -> 280
A12: 1187 | B12: 44959 | C12: 19 | D12: 594 | E12: 6 | F12: =VLOOKUP(orders[[#All],[customer_id]],'customers'!A:B,2,0) -> ahmeD | G12: =INDEX(products!A:G,MATCH(orders[[#This Row],[product_id]],products[[#All],[product_id]],0),MATCH("product_name",products[#Headers],0)) -> Chicken | H12: =VLOOKUP(orders[[#This Row],[product_id]],products!A:G,7,FALSE) -> ₹250 | I12: =SUM(orders[[#This Row],[qty]]*orders[[#This Row],[price (in INR)]]) -> 1500
A13: 1193 | B13: 44960 | C13: 34 | D13: 651 | E13: 2 | F13: =VLOOKUP(orders[[#All],[customer_id]],'customers'!A:B,2,0) -> JaY | G13: =INDEX(products!A:G,MATCH(orders[[#This Row],[product_id]],products[[#All],[product_id]],0),MATCH("product_name",products[#Headers],0)) -> Banana | H13: =VLOOKUP(orders[[#This Row],[product_id]],products!A:G,7,FALSE) -> ₹80 | I13: =SUM(orders[[#This Row],[qty]]*orders[[#This Row],[price (in INR)]]) -> 160
... A15: 1195 | B15: 44960 | C15: 29 | D15: 739 | E15: 3 | F15: =VLOOKUP(orders[[#All],[customer_id]],'customers'!A:B,2,0) -> johN | G15: =INDEX(products!A:G,MATCH(orders[[#This Row],[product_id]],products[[#All],[product_id]],0),MATCH("product_name",products[#Headers],0)) -> Donut | H15: =VLOOKUP(orders[[#This Row],[product_id]],products!A:G,7,FALSE) -> ₹40 | I15: =SUM(orders[[#This Row],[qty]]*orders[[#This Row],[price (in INR)]]) -> 120
A16: 1199 | B16: 44960 | C16: 35 | D16: 797 | F16: =VLOOKUP(orders[[#All],[customer_id]],'customers'!A:B,2,0) -> MiKe | G16: =INDEX(products!A:G,MATCH(orders[[#This Row],[product_id]],products[[#All],[product_id]],0),MATCH("product_name",products[#Headers],0)) -> Cheese | H16: =VLOOKUP(orders[[#This Row],[product_id]],products!A:G,7,FALSE) -> ₹80 | I16: =SUM(orders[[#This Row],[qty]]*orders[[#This Row],[price (in INR)]]) -> 0
A17: 1200 | B17: 44960 | C17: 79 | D17: 521 | E17: 3 | F17: =VLOOKUP(orders[[#All],[customer_id]],'customers'!A:B,2,0) -> TiM | G17: =INDEX(products!A:G,MATCH(orders[[#This Row],[product_id]],products[[#All],[product_id]],0),MATCH("product_name",products[#Headers],0)) -> Carrot | H17: =VLOOKUP(orders[[#This Row],[product_id]],products!A:G,7,FALSE) -> ₹40 | I17: =SUM(orders[[#This Row],[qty]]*orders[[#This Row],[price (in INR)]]) -> 120
A18: 1206 | B18: 44961 | C18: 11 | D18: 886 | F18: =VLOOKUP(orders[[#All],[customer_id]],'customers'!A:B,2,0) -> AnthoNY | G18: =INDEX(products!A:G,MATCH(orders[[#This Row],[product_id]],products[[#All],[product_id]],0),MATCH("product_name",products[#Headers],0)) -> Avocado | H18: =VLOOKUP(orders[[#This Row],[product_id]],products!A:G,7,FALSE) -> ₹100 | I18: =SUM(orders[[#This Row],[qty]]*orders[[#This Row],[price (in INR)]]) -> 0
A19: 1211 | B19: 44961 | C19: 79 | D19: 646 | E19: 7 | F19: =VLOOKUP(orders[[#All],[customer_id]],'customers'!A:B,2,0) -> TiM | G19: =INDEX(products!A:G,MATCH(orders[[#This Row],[product_id]],products[[#All],[product_id]],0),MATCH("product_name",products[#Headers],0)) -> Apple | H19: =VLOOKUP(orders[[#This Row],[product_id]],products!A:G,7,FALSE) -> ₹200 | I19: =SUM(orders[[#This Row],[qty]]*orders[[#This Row],[price (in INR)]]) -> 1400
A20: 1213 | B20: 44961 | C20: 29 | D20: 328 | E20: 10 | F20: =VLOOKUP(orders[[#All],[customer_id]],'customers'!A:B,2,0) -> johN | G20: =INDEX(products!A:G,MATCH(orders[[#This Row],[product_id]],products[[#All],[product_id]],0),MATCH("product_name",products[#Headers],0)) -> Pasta | H20: =VLOOKUP(orders[[#This Row],[product_id]],products!A:G,7,FALSE) -> ₹60 | I20: =SUM(orders[[#This Row],[qty]]*orders[[#This Row],[price (in INR)]]) -> 600
A21: 1215 | B21: 44961 | C21: 21 | D21: 811 | E21: 3 | F21: =VLOOKUP(orders[[#All],[customer_id]],'customers'!A:B,2,0) -> Lisa | G21: =INDEX(products!A:G,MATCH(orders[[#This Row],[product_id]],products[[#All],[product_id]],0),MATCH("product_name",products[#Headers],0)) -> Celery | H21: =VLOOKUP(orders[[#This Row],[product_id]],products!A:G,7,FALSE) -> ₹50 | I21: =SUM(orders[[#This Row],[qty]]*orders[[#This Row],[price (in INR)]]) -> 150
A22: 1227 | B22: 44961 | C22: 50 | D22: 704 | E22: 5 | F22: =VLOOKUP(orders[[#All],[customer_id]],'customers'!A:B,2,0) -> BRuce | G22: =INDEX(products!A:G,MATCH(orders[[#This Row],[product_id]],products[[#All],[product_id]],0),MATCH("product_name",products[#Headers],0)) -> Eggs | H22: =VLOOKUP(orders[[#This Row],[product_id]],products!A:G,7,FALSE) -> ₹65 | I22: =SUM(orders[[#This Row],[qty]]*orders[[#This Row],[price (in INR)]]) -> 325
A23: 1233 | B23: 44962 | C23: 79 | D23: 328 | E23: 10 | F23: =VLOOKUP(orders[[#All],[customer_id]],'customers'!A:B,2,0) -> TiM | G23: =INDEX(products!A:G,MATCH(orders[[#This Row],[product_id]],products[[#All],[product_id]],0),MATCH("product_name",products[#Headers],0)) -> Pasta | H23: =VLOOKUP(orders[[#This Row],[product_id]],products!A:G,7,FALSE) -> ₹60 | I23: =SUM(orders[[#This Row],[qty]]*orders[[#This Row],[price (in INR)]]) -> 600
A24: 1235 | B24: 44962 | C24: 14 | D24: 163 | E24: 10 | F24: =VLOOKUP(orders[[#All],[customer_id]],'customers'!A:B,2,0) -> RavI | G24: =INDEX(products!A:G,MATCH(orders[[#This Row],[product_id]],products[[#All],[product_id]],0),MATCH("product_name",products[#Headers],0)) -> Grape Juice | H24: =VLOOKUP(orders[[#This Row],[product_id]],products!A:G,7,FALSE) -> ₹40 | I24: =SUM(orders[[#This Row],[qty]]*orders[[#This Row],[price (in INR)]]) -> 400
A25: 1255 | B25: 44962 | C25: 50 | D25: 521 | E25: 2 | F25: =VLOOKUP(orders[[#All],[customer_id]],'customers'!A:B,2,0) -> BRuce | G25: =INDEX(products!A:G,MATCH(orders[[#This Row],[product_id]],products[[#All],[product_id]],0),MATCH("product_name",products[#Headers],0)) -> Carrot | H25: =VLOOKUP(orders[[#This Row],[product_id]],products!A:G,7,FALSE) -> ₹40 | I25: =SUM(orders[[#This Row],[qty]]*orders[[#This Row],[price (in INR)]]) -> 80
A26: 1257 | B26: 44962 | C26: 11 | D26: 590 | E26: 8 | F26: =VLOOKUP(orders[[#All],[customer_id]],'customers'!A:B,2,0) -> AnthoNY | G26: =INDEX(products!A:G,MATCH(orders[[#This Row],[product_id]],products[[#All],[product_id]],0),MATCH("product_name",products[#Headers],0)) -> French Fries | H26: =VLOOKUP(orders[[#This Row],[product_id]],products!A:G,7,FALSE) -> ₹50 | I26: =SUM(orders[[#This Row],[qty]]*orders[[#This Row],[price (in INR)]]) -> 400
A27: 1258 | B27: 44962 | C27: 34 | D27: 704 | E27: 4 | F27: =VLOOKUP(orders[[#All],[customer_id]],'customers'!A:B,2,0) -> JaY | G27: =INDEX(products!A:G,MATCH(orders[[#This Row],[product_id]],products[[#All],[product_id]],0),MATCH("product_name",products[#Headers],0)) -> Eggs | H27: =VLOOKUP(orders[[#This Row],[product_id]],products!A:G,7,FALSE) -> ₹65 | I27: =SUM(orders[[#This Row],[qty]]*orders[[#This Row],[price (in INR)]]) -> 260
A28: 1273 | B28: 44963 | C28: 50 | D28: 886 | E28: 3 | F28: =VLOOKUP(orders[[#All],[customer_id]],'customers'!A:B,2,0) -> BRuce | G28: =INDEX(products!A:G,MATCH(orders[[#This Row],[product_id]],products[[#All],[product_id]],0),MATCH("product_name",products[#Headers],0)) -> Avocado | H28: =VLOOKUP(orders[[#This Row],[product_id]],products!A:G,7,FALSE) -> ₹100 | I28: =SUM(orders[[#This Row],[qty]]*orders[[#This Row],[price (in INR)]]) -> 300
A29: 1277 | B29: 44963 | C29: 34 | D29: 704 | E29: 6 | F29: =VLOOKUP(orders[[#All],[customer_id]],'customers'!A:B,2,0) -> JaY | G29: =INDEX(products!A:G,MATCH(orders[[#This Row],[product_id]],products[[#All],[product_id]],0),MATCH("product_name",products[#Headers],0)) -> Eggs | H29: =VLOOKUP(orders[[#This Row],[product_id]],products!A:G,7,FALSE) -> ₹65 | I29: =SUM(orders[[#This Row],[qty]]*orders[[#This Row],[price (in INR)]]) -> 390
A30: 1289 | B30: 44963 | C30: 19 | D30: 811 | E30: 6 | F30: =VLOOKUP(orders[[#All],[customer_id]],'customers'!A:B,2,0) -> ahmeD | G30: =INDEX(products!A:G,MATCH(orders[[#This Row],[product_id]],products[[#All],[product_id]],0),MATCH("product_name",products[#Headers],0)) -> Celery | H30: =VLOOKUP(orders[[#This Row],[product_id]],products!A:G,7,FALSE) -> ₹50 | I30: =SUM(orders[[#This Row],[qty]]*orders[[#This Row],[price (in INR)]]) -> 300
... A38: 1302 | B38: 44964 | C38: 34 | D38: 328 | E38: 3 | F38: =VLOOKUP(orders[[#All],[customer_id]],'customers'!A:B,2,0) -> JaY | G38: =INDEX(products!A:G,MATCH(orders[[#This Row],[product_id]],products[[#All],[product_id]],0),MATCH("product_name",products[#Headers],0)) -> Pasta | H38: =VLOOKUP(orders[[#This Row],[product_id]],products!A:G,7,FALSE) -> ₹60 | I38: =SUM(orders[[#This Row],[qty]]*orders[[#This Row],[price (in INR)]]) -> 180
A39: 1309 | B39: 44965 | C39: 34 | D39: 163 | F39: =VLOOKUP(orders[[#All],[customer_id]],'customers'!A:B,2,0) -> JaY | G39: =INDEX(products!A:G,MATCH(orders[[#This Row],[product_id]],products[[#All],[product_id]],0),MATCH("product_name",products[#Headers],0)) -> Grape Juice | H39: =VLOOKUP(orders[[#This Row],[product_id]],products!A:G,7,FALSE) -> ₹40 | I39: =SUM(orders[[#This Row],[qty]]*orders[[#This Row],[price (in INR)]]) -> 0
A40: 1310 | B40: 44965 | C40: 79 | D40: 484 | E40: 3 | F40: =VLOOKUP(orders[[#All],[customer_id]],'customers'!A:B,2,0) -> TiM | G40: =INDEX(products!A:G,MATCH(orders[[#This Row],[product_id]],products[[#All],[product_id]],0),MATCH("product_name",products[#Headers],0)) -> Hamburger | H40: =VLOOKUP(orders[[#This Row],[product_id]],products!A:G,7,FALSE) -> ₹70 | I40: =SUM(orders[[#This Row],[qty]]*orders[[#This Row],[price (in INR)]]) -> 210
A41: 1318 | B41: 44965 | C41: 29 | D41: 794 | E41: 3 | F41: =VLOOKUP(orders[[#All],[customer_id]],'customers'!A:B,2,0) -> johN | G41: =INDEX(products!A:G,MATCH(orders[[#This Row],[product_id]],products[[#All],[product_id]],0),MATCH("product_name",products[#Headers],0)) -> Grilled Cheese | H41: =VLOOKUP(orders[[#This Row],[product_id]],products!A:G,7,FALSE) -> ₹100 | I41: =SUM(orders[[#This Row],[qty]]*orders[[#This Row],[price (in INR)]]) -> 300
A42: 1319 | B42: 44965 | C42: 14 | D42: 521 | E42: 6 | F42: =VLOOKUP(orders[[#All],[customer_id]],'customers'!A:B,2,0) -> RavI | G42: =INDEX(products!A:G,MATCH(orders[[#This Row],[product_id]],products[[#All],[product_id]],0),MATCH("product_name",products[#Headers],0)) -> Carrot | H42: =VLOOKUP(orders[[#This Row],[product_id]],products!A:G,7,FALSE) -> ₹40 | I42: =SUM(orders[[#This Row],[qty]]*orders[[#This Row],[price (in INR)]]) -> 240
A43: 1321 | B43: 44965 | C43: 21 | D43: 594 | E43: 7 | F43: =VLOOKUP(orders[[#All],[customer_id]],'customers'!A:B,2,0) -> Lisa | G43: =INDEX(products!A:G,MATCH(orders[[#This Row],[product_id]],products[[#All],[product_id]],0),MATCH("product_name",products[#Headers],0)) -> Chicken | H43: =VLOOKUP(orders[[#This Row],[product_id]],products!A:G,7,FALSE) -> ₹250 | I43: =SUM(orders[[#This Row],[qty]]*orders[[#This Row],[price (in INR)]]) -> 1750
A44: 1323 | B44: 44966 | C44: 79 | D44: 646 | E44: 9 | F44: =VLOOKUP(orders[[#All],[customer_id]],'customers'!A:B,2,0) -> TiM | G44: =INDEX(products!A:G,MATCH(orders[[#This Row],[product_id]],products[[#All],[product_id]],0),MATCH("product_name",products[#Headers],0)) -> Apple | H44: =VLOOKUP(orders[[#This Row],[product_id]],products!A:G,7,FALSE) -> ₹200 | I44: =SUM(orders[[#This Row],[qty]]*orders[[#This Row],[price (in INR)]]) -> 1800
A45: 1324 | B45: 44966 | C45: 19 | D45: 594 | E45: 8 | F45: =VLOOKUP(orders[[#All],[customer_id]],'customers'!A:B,2,0) -> ahmeD | G45: =INDEX(products!A:G,MATCH(orders[[#This Row],[product_id]],products[[#All],[product_id]],0),MATCH("product_name",products[#Headers],0)) -> Chicken | H45: =VLOOKUP(orders[[#This Row],[product_id]],products!A:G,7,FALSE) -> ₹250 | I45: =SUM(orders[[#This Row],[qty]]*orders[[#This Row],[price (in INR)]]) -> 2000
A46: 1327 | B46: 44966 | C46: 50 | D46: 392 | E46: 9 | F46: =VLOOKUP(orders[[#All],[customer_id]],'customers'!A:B,2,0) -> BRuce | G46: =INDEX(products!A:G,MATCH(orders[[#This Row],[product_id]],products[[#All],[product_id]],0),MATCH("product_name",products[#Headers],0)) -> Yogurt | H46: =VLOOKUP(orders[[#This Row],[product_id]],products!A:G,7,FALSE) -> ₹30 | I46: =SUM(orders[[#This Row],[qty]]*orders[[#This Row],[price (in INR)]]) -> 270
A47: 1330 | B47: 44966 | C47: 29 | D47: 804 | E47: 10 | F47: =VLOOKUP(orders[[#All],[customer_id]],'customers'!A:B,2,0) -> johN | G47: =INDEX(products!A:G,MATCH(orders[[#This Row],[product_id]],products[[#All],[product_id]],0),MATCH("product_name",products[#Headers],0)) -> Broccoli | H47: =VLOOKUP(orders[[#This Row],[product_id]],products!A:G,7,FALSE) -> ₹30 | I47: =SUM(orders[[#This Row],[qty]]*orders[[#This Row],[price (in INR)]]) -> 300
A48: 1335 | B48: 44966 | C48: 34 | D48: 811 | E48: 6 | F48: =VLOOKUP(orders[[#All],[customer_id]],'customers'!A:B,2,0) -> JaY | G48: =INDEX(products!A:G,MATCH(orders[[#This Row],[product_id]],products[[#All],[product_id]],0),MATCH("product_name",products[#Headers],0)) -> Celery | H48: =VLOOKUP(orders[[#This Row],[product_id]],products!A:G,7,FALSE) -> ₹50 | I48: =SUM(orders[[#This Row],[qty]]*orders[[#This Row],[price (in INR)]]) -> 300
...

Sheet products
A1: product_id | B1: product_name | C1: calories | D1: protein | E1: carbs | F1: fat | G1: price (in INR)
A2: 646 | B2: Apple | C2: 52 | D2: 0.26 | E2: 13.8 | F2: 0.17 | G2: ₹200
A3: 651 | B3: Banana | C3: 89 | D3: 1.09 | E3: 22.8 | F3: 0.33 | G3: ₹80
A4: 886 | B4: Avocado | C4: 322 | D4: 4.02 | E4: 17.15 | F4: 29.47 | G4: ₹100
A5: 804 | B5: Broccoli | C5: 34 | D5: 2.82 | E5: 6.64 | F5: 0.37 | G5: ₹30
A6: 594 | B6: Chicken | C6: 335 | D6: 31.02 | E6: 0 | F6: 23.11 | G6: ₹250
A7: 628 | B7: Fish | C7: 206 | D7: 20.26 | E7: 0 | F7: 13.92 | G7: ₹120
A8: 294 | B8: Rice | C8: 130 | D8: 2.69 | E8: 28.73 | F8: 0.28 | G8: ₹80
A9: 328 | B9: Pasta | C9: 131 | D9: 5.47 | E9: 25.77 | F9: 1.03 | G9: ₹60
A10: 521 | B10: Carrot | C10: 41 | D10: 0.93 | E10: 9.58 | F10: 0.24 | G10: ₹40
A11: 811 | B11: Celery | C11: 16 | D11: 0.69 | E11: 3.06 | F11: 0.17 | G11: ₹50
A12: 797 | B12: Cheese | C12: 402 | D12: 25.09 | E12: 3.09 | F12: 33.82 | G12: ₹80
A13: 862 | B13: Chocolate Cake | C13: 452 | D13: 3.75 | E13: 44.61 | F13: 29.11 | G13: ₹200
... A21: 484 | B21: Hamburger | C21: 250 | D21: 13.29 | E21: 17.32 | F21: 14.62 | G21: ₹70

Sheet customers
A1: customer_id | B1: customer_name
A2: 34 | B2: JaY
A3: 29 | B3: johN
A4: 79 | B4: TiM
A5: 14 | B5: RavI
A6: 21 | B6: Lisa
A7: 19 | B7: ahmeD
A8: 35 | B8: MiKe
A9: 50 | B9: BRuce
A10: 35 | B10: MahESh
A11: 11 | B11: AnthoNY
